Workbook

Sheet ExcusionSales
A1: Date | B1: 05.09.2026 | C1: 05.09.2026 | D1: 06.09.2026 | E1: 06.09.2026 | F1: 01.09.2026 | G1: 02.09.2026 | H1: 02.09.2026 | I1: 03.09.2026 | J1: 04.09.2026 | K1: 04.09.2026 | L1: 03.09.2026
A2: EURO | B2: 40 | C2: 50 | D2: 60 | E2: 65 | F2: 40 | G2: 60 | H2: 70 | I2: 40 | J2: 100 | L2: 65
A3: Isim Soyad | B3: 1-PRG-Dresden | C3: 2-PRG-Boat | D3: 3-PRG-KV | E3: 4-PRG-Folklor | F3: 5-BDP-Boat | G3: 6-BDP-Estergom | H3: 7-BDP-VDP | I3: 8-BDP-Brt | J3: 9-VN-Hallstat | K3: 10-VN-Gringsing | L3: 11-VN-Concert | M3: SUM(Children discount) | N3: =SUM(B53:J53,L53) -> -120
A4: AYSUNUYGUN | B4: TRUE | C4: TRUE | D4: TRUE | E4: TRUE | F4: TRUE | G4: TRUE | H4: TRUE | I4: TRUE | J4: TRUE | L4: TRUE | N4: FALSE
A5: Mehmet BarışAltun | B5: TRUE | C5: TRUE | D5: TRUE | E5: FALSE | F5: TRUE | G5: TRUE | H5: TRUE | I5: FALSE | J5: TRUE | L5: FALSE | N5: FALSE
A6: TugbaAltun | B6: TRUE | C6: TRUE | D6: TRUE | E6: FALSE | F6: TRUE | G6: TRUE | H6: TRUE | I6: FALSE | J6: TRUE | L6: FALSE | N6: FALSE
A7: Gül CananFettahlıoğlu | B7: TRUE | C7: FALSE | D7: TRUE | E7: FALSE | F7: TRUE | G7: TRUE | H7: FALSE | I7: TRUE | J7: FALSE | L7: FALSE | N7: FALSE
A8: Ramazan YaşarFettahlıoğlu | B8: TRUE | C8: FALSE | D8: TRUE | E8: FALSE | F8: TRUE | G8: TRUE | H8: FALSE | I8: TRUE | J8: FALSE | L8: FALSE | N8: FALSE | O8: 860 eu
A9: Samiye NurFettahlıoğlu | B9: TRUE | C9: FALSE | D9: TRUE | F9: TRUE | G9: TRUE | H9: FALSE | I9: TRUE | J9: FALSE | L9: FALSE | N9: FALSE
A10: Abdullah CemFettahlıoğlu | C10: FALSE | D10: FALSE | E10: FALSE | F10: TRUE | G10: TRUE | H10: FALSE | I10: TRUE | J10: FALSE | L10: FALSE | N10: FALSE
A11: VacideSever | B11: TRUE | C11: FALSE | D11: TRUE | E11: FALSE | F11: TRUE | G11: TRUE | H11: FALSE | I11: TRUE | J11: FALSE | L11: FALSE | N11: FALSE
A12: MetinMutlu | B12: TRUE | C12: FALSE | D12: TRUE | E12: FALSE | F12: TRUE | G12: TRUE | H12: FALSE | I12: TRUE | J12: FALSE | L12: FALSE | N12: FALSE
A13: İBRAHİM HALİLERTAN | B13: TRUE | C13: FALSE | D13: TRUE | E13: FALSE | F13: FALSE | G13: TRUE | H13: FALSE | I13: TRUE | J13: FALSE | L13: FALSE | N13: FALSE
A14: TUBAERTAN | B14: TRUE | C14: FALSE | D14: TRUE | E14: FALSE | F14: FALSE | G14: TRUE | H14: FALSE | I14: TRUE | J14: FALSE | L14: FALSE | N14: FALSE
A15: BÜŞRA NEVİNERTAN | B15: FALSE | C15: FALSE | D15: FALSE | E15: FALSE | F15: FALSE | G15: FALSE | H15: FALSE | I15: FALSE | J15: FALSE | L15: FALSE | N15: FALSE
A16: HATİCEKUŞ KARAKURT | B16: TRUE | C16: FALSE | D16: FALSE | E16: FALSE | F16: TRUE | G16: FALSE | H16: FALSE | I16: FALSE | J16: FALSE | L16: FALSE | N16: FALSE
A17: ALPTEKİNKARAKURT | B17: TRUE | C17: FALSE | D17: FALSE | E17: FALSE | F17: TRUE | G17: FALSE | H17: FALSE | I17: FALSE | J17: FALSE | L17: FALSE | N17: FALSE
A18: ASYA BALIMKARAKURT | B18: FALSE | C18: FALSE | D18: FALSE | E18: FALSE | F18: TRUE | G18: FALSE | H18: FALSE | I18: FALSE | J18: FALSE | L18: FALSE | N18: FALSE
A19: DAMLAKİREMİTCİ | B19: TRUE | C19: TRUE | D19: TRUE | E19: FALSE | F19: FALSE | G19: FALSE | H19: FALSE | I19: TRUE | J19: FALSE | L19: FALSE | N19: FALSE
A20: ALTANKİREMİTCİ | B20: TRUE | C20: TRUE | D20: TRUE | E20: FALSE | F20: FALSE | G20: FALSE | H20: FALSE | I20: TRUE | J20: FALSE | L20: FALSE | N20: FALSE
A21: ARYAKİREMİTCİ | B21: FALSE | C21: FALSE | D21: FALSE | E21: FALSE | F21: FALSE | G21: FALSE | H21: FALSE | I21: FALSE | J21: FALSE | L21: FALSE | N21: FALSE
A22: EMİNEDUZ | B22: TRUE | C22: TRUE | D22: FALSE | E22: FALSE | F22: TRUE | G22: TRUE | H22: FALSE | I22: FALSE | J22: TRUE | L22: FALSE | N22: FALSE
... A28: ASİYEUYGUN | B28: TRUE | C28: TRUE | D28: FALSE | E28: FALSE | F28: FALSE | G28: TRUE | H28: FALSE | I28: FALSE | J28: TRUE | L28: FALSE | N28: FALSE
A29: DEMİRUYGUN | B29: FALSE | C29: TRUE | D29: FALSE | E29: FALSE | F29: FALSE | G29: FALSE | H29: FALSE | I29: FALSE | J29: TRUE | L29: FALSE | N29: FALSE | O29: =SUM(O4:O23) -> 0
A30: BARIŞUYGUN | B30: FALSE | C30: TRUE | D30: FALSE | E30: FALSE | F30: FALSE | G30: FALSE | H30: FALSE | I30: FALSE | J30: FALSE | L30: FALSE | N30: FALSE
A31: EMELİNAN | B31: TRUE | C31: TRUE | D31: FALSE | E31: FALSE | F31: TRUE | G31: FALSE | H31: FALSE | I31: FALSE | J31: TRUE | L31: FALSE | N31: FALSE
A32: ZAFERİNAN | B32: TRUE | C32: TRUE | D32: FALSE | E32: FALSE | F32: TRUE | G32: FALSE | H32: FALSE | I32: FALSE | J32: TRUE | L32: FALSE | N32: FALSE
A33: ASİLİNAN | B33: FALSE | C33: TRUE | D33: FALSE | E33: FALSE | F33: FALSE | G33: FALSE | H33: FALSE | I33: FALSE | J33: FALSE | L33: FALSE | N33: FALSE
A34: DEMİRİNAN | B34: FALSE | C34: TRUE | D34: FALSE | E34: FALSE | F34: FALSE | G34: FALSE | H34: FALSE | I34: FALSE | J34: FALSE | L34: FALSE | N34: FALSE | O34: 46276
A35: M. HUSEYINKIMYONOGLU | B35: TRUE | C35: TRUE | D35: FALSE | E35: TRUE | F35: TRUE | G35: TRUE | H35: FALSE | I35: TRUE | J35: TRUE | L35: FALSE | N35: FALSE
A36: INANCKIMYONOGLU | B36: TRUE | C36: TRUE | D36: FALSE | E36: TRUE | F36: TRUE | G36: TRUE | H36: FALSE | I36: TRUE | J36: TRUE | L36: FALSE | N36: FALSE
A37: MEHMET LUTFIKIMYONOGLU | B37: TRUE | C37: TRUE | D37: FALSE | E37: TRUE | F37: TRUE | G37: TRUE | H37: FALSE | I37: TRUE | J37: TRUE | L37: FALSE | N37: FALSE
A38: AZRAKIMYONOGLU | B38: FALSE | C38: TRUE | D38: FALSE | E38: TRUE | F38: TRUE | G38: FALSE | H38: FALSE | I38: FALSE | J38: TRUE | L38: FALSE | N38: FALSE
A39: SEMRAKEZBAN ARSLAN | B39: TRUE | C39: TRUE | D39: TRUE | E39: TRUE | F39: TRUE | G39: TRUE | H39: FALSE | I39: TRUE | J39: TRUE | L39: FALSE | N39: FALSE
A40: ARZUSASMAZ | B40: TRUE | C40: TRUE | D40: FALSE | E40: TRUE | F40: FALSE | G40: TRUE | H40: FALSE | I40: TRUE | J40: TRUE | L40: FALSE | N40: FALSE
A41: MUNTECEPSANLI | B41: TRUE | C41: TRUE | D41: TRUE | E41: TRUE | F41: FALSE | G41: TRUE | H41: FALSE | I41: TRUE | J41: TRUE | L41: FALSE | N41: FALSE
A42: SABAHATŞANLI | B42: TRUE | C42: FALSE | D42: TRUE | E42: TRUE | F42: FALSE | G42: TRUE | H42: FALSE | I42: TRUE | J42: TRUE | L42: FALSE | N42: FALSE
A43: HAYDAR ERCAN | B43: TRUE | C43: FALSE | D43: TRUE | E43: TRUE | F43: TRUE | G43: TRUE | H43: TRUE | I43: TRUE | J43: TRUE | L43: FALSE | N43: FALSE
A44: SİBEL ERCAN | B44: TRUE | C44: FALSE | D44: TRUE | E44: TRUE | F44: TRUE | G44: TRUE | H44: TRUE | I44: TRUE | J44: TRUE | L44: FALSE | N44: FALSE
A45: HİLAL SANLI | B45: TRUE | C45: TRUE | D45: TRUE | E45: TRUE | F45: TRUE | G45: TRUE | H45: FALSE | I45: TRUE | J45: TRUE | L45: FALSE | N45: FALSE
...

Sheet BaseServices
A1: Base Service | B1: Revenue | C1: Expense | D1: Other | E1: per/Pax | F1: UnitPrice | G1: Adult | H1: Children | I1: Infant | J1: Total
A2: Agengy Fee | B2: TRUE | C2: FALSE | D2: FALSE | E2: TRUE | F2: 200 | G2: 42 | H2: 3 | I2: 2 | J2: =(G2*F2) + (H2*0.5* F2) -> 8700
A3: CityTax | B3: TRUE | C3: FALSE | D3: FALSE | E3: TRUE | F3: 30 | G3: 47 | J3: =(F3*G3) -> 1410

Sheet ServicesList
A1: Services
A2: Hotel
A3: Flight
A4: Transport
A5: Guide
A6: Driver
A7: Excursion
A8: Invoiced Fee
A9: Parking
A10: Tips
A11: City Tax

Sheet Oteller
A2: 3* PrimeStay Budapest | B2: https://www.primestaysbudapest.com/ | C2: Address: Budapest, Országbíró u. 44-46, 1139 Hungary | D2: Phone: +36 30 517 0471
A3: 5*Grand Plaza Hotel | B3: https://www.grandplazahotel.si/ | C3: Address: Slovenska cesta 60, 1000 Ljubljana, Slovenia | D3: Phone: +386 1 243 01 00
A4: 4*Hotel Blue | B4: https://www.hotelblue.eu/en/ | C4: Address: Ul. grada Vukovara 20, 10000, Zagreb, Croatia | D4: Phone: +385 1 3333 600
A5: 4*SLEEEP Hotel Vösendorf | B5: https://www.sleeep-hotel.at/en | C5: Adres: Nordring 20, 2334 Vösendorf | D5: Tel: +43 7243 52052-23

Sheet Track
A1: Tasks | B1: Pre | C1: Day1 | D1: Day2 | E1: Day3 | F1: Day4 | G1: Day5 | H1: Day6 | I1: Day7 | J1: Day8
A2: Otel Reservasyon oda check | B2: FALSE | C2: FALSE | D2: FALSE | E2: FALSE | F2: FALSE | G2: FALSE | H2: FALSE | I2: FALSE | J2: FALSE
A3: Tuna Tekne Rez | B3: FALSE | C3: TRUE | D3: FALSE | E3: FALSE | F3: FALSE | G3: FALSE | H3: FALSE | I3: FALSE | J3: FALSE | K3: =82000/360 -> 227.77778
A4: Cigan Rez | B4: FALSE | C4: FALSE | D4: TRUE | E4: FALSE | F4: FALSE | G4: FALSE | H4: FALSE | I4: FALSE | J4: FALSE | K4: 360
A5: Ronesans Rez. | B5: FALSE | C5: FALSE | D5: TRUE | E5: FALSE | F5: FALSE | G5: FALSE | H5: FALSE | I5: FALSE | J5: FALSE
A6: Ginzing Rez. | B6: FALSE | C6: FALSE | D6: FALSE | E6: FALSE | F6: FALSE | G6: FALSE | H6: FALSE | I6: TRUE | J6: FALSE
A7: Venedik | B7: FALSE | C7: FALSE | D7: FALSE | E7: FALSE | F7: FALSE | G7: FALSE | H7: FALSE | I7: FALSE | J7: FALSE
B8: FALSE | C8: FALSE | D8: FALSE | E8: FALSE | F8: FALSE | G8: FALSE | H8: FALSE | I8: FALSE | J8: FALSE
K9: =SUM(K3:K8) -> 587.77778
C10: 46164 | D10: 46165 | E10: 46166 | F10: 46167 | G10: 46168 | H10: 46169 | I10: 46170 | J10: 46171
K11: =2200-K9 -> 1612.2222

Sheet Harcamalar
A1: PCS 1107 BE-PBV - Harcamalar / Giderler
L2: CZK per EUR
A3: Tur No | B3: Tur | C3: Gider Kalemi | D3: Belge / Tedarikçi | E3: Tarih | F3: Para Birimi | G3: Belge Tutarı | H3: CZK/EUR Kuru | I3: EUR Karşılığı | J3: Not
A4: 1 | B4: 1-Dresden | C4: Havalimanı otoparkı | D4: APCOA Parking – BER Airport | E4: 11.07.2026 | F4: EUR | H4: =$M$2 -> 0 | I4: =IF(F4="EUR",IF(ISNUMBER(G4),G4,0),IF(AND(F4="CZK",ISNUMBER(G4),$M$2>0),G4/$M$2,0)) -> 0 | J4: Bilette ücret görünmüyor; tutar gerekli.
A5: 1 | B5: 1-Dresden | C5: Berlin–Prag ulaşımı | D5: FlixBus booking #3368840110 | E5: 28.06.2026 | F5: CZK | G5: 738 | H5: =$M$2 -> 0 | I5: =IF(F5="EUR",IF(ISNUMBER(G5),G5,0),IF(AND(F5="CZK",ISNUMBER(G5),$M$2>0),G5/$M$2,0)) -> 0 | J5: 729 CZK bilet + 9 CZK servis ücreti.
A6: 2 | B6: 2-Tekne | C6: Vltava tekne gideri | D6: Loď MORAVIA / Na Františku | E6: 13.07.2026 | F6: EUR | G6: 662 | H6: =$M$2 -> 0 | I6: =IF(F6="EUR",IF(ISNUMBER(G6),G6,0),IF(AND(F6="CZK",ISNUMBER(G6),$M$2>0),G6/$M$2,0)) -> 662 | J6: El yazısı tutar 662 olarak okunuyor; teyit önerilir.
A7: 3 | B7: 3-KV | C7: Karlovy Vary otoparkı | D7: Dopravní podnik Karlovy Vary | E7: 13.07.2026 | F7: CZK | G7: 390 | H7: =$M$2 -> 0 | I7: =IF(F7="EUR",IF(ISNUMBER(G7),G7,0),IF(AND(F7="CZK",ISNUMBER(G7),$M$2>0),G7/$M$2,0)) -> 0 | J7: Parkoviště Kome 32.
A8: 4 | B8: 4-Çek G. | C8: Folklor gösterisi | D8: Folklore Garden s.r.o. | E8: 12.07.2026 | F8: EUR | G8: 710 | H8: =$M$2 -> 0 | I8: =IF(F8="EUR",IF(ISNUMBER(G8),G8,0),IF(AND(F8="CZK",ISNUMBER(G8),$M$2>0),G8/$M$2,0)) -> 710 | J8: Belgede 703 + 7 EUR; 18 yetişkin + 2 çocuk.
A9: 5 | B9: 5-Tuna T. | C9: Şimdilik gider yok | F9: EUR | G9: 0 | H9: =$M$2 -> 0 | I9: =IF(F9="EUR",IF(ISNUMBER(G9),G9,0),IF(AND(F9="CZK",ISNUMBER(G9),$M$2>0),G9/$M$2,0)) -> 0 | J9: Kullanıcı talebiyle 0.
A10: 6 | B10: 6-Estergom | C10: Şimdilik gider yok | F10: EUR | G10: 0 | H10: =$M$2 -> 0 | I10: =IF(F10="EUR",IF(ISNUMBER(G10),G10,0),IF(AND(F10="CZK",ISNUMBER(G10),$M$2>0),G10/$M$2,0)) -> 0 | J10: Kullanıcı talebiyle 0.
A11: 7 | B11: 7-Çigan | C11: Şimdilik gider yok | F11: EUR | G11: 0 | H11: =$M$2 -> 0 | I11: =IF(F11="EUR",IF(ISNUMBER(G11),G11,0),IF(AND(F11="CZK",ISNUMBER(G11),$M$2>0),G11/$M$2,0)) -> 0 | J11: Kullanıcı talebiyle 0.
A12: 8 | B12: 8-Bratislava | C12: Şimdilik gider yok | F12: EUR | G12: 0 | H12: =$M$2 -> 0 | I12: =IF(F12="EUR",IF(ISNUMBER(G12),G12,0),IF(AND(F12="CZK",ISNUMBER(G12),$M$2>0),G12/$M$2,0)) -> 0 | J12: Kullanıcı talebiyle 0.
A13: 9 | B13: 9-Hallstatt | C13: Şimdilik gider yok | F13: EUR | G13: 0 | H13: =$M$2 -> 0 | I13: =IF(F13="EUR",IF(ISNUMBER(G13),G13,0),IF(AND(F13="CZK",ISNUMBER(G13),$M$2>0),G13/$M$2,0)) -> 0 | J13: Kullanıcı talebiyle 0.
A14: 10 | B14: 10-Konser | C14: Şimdilik gider yok | F14: EUR | G14: 0 | H14: =$M$2 -> 0 | I14: =IF(F14="EUR",IF(ISNUMBER(G14),G14,0),IF(AND(F14="CZK",ISNUMBER(G14),$M$2>0),G14/$M$2,0)) -> 0 | J14: Kullanıcı talebiyle 0.
A16: TOPLAM BELGELİ GİDER | I16: =SUM(I4:I14) -> 1372
A18: Önceden bildirilen toplam gider | I18: 1442
A19: Fark / Açıklanmayan tutar | I19: =I18-I16 -> 70

Sheet SatisOzet
A1: PCS 1107 BE-PBV - Satış Özeti
G2: Grand Total Reconciliation
A3: Tur | B3: Acente Paket Satış | C3: Ersen Paket Satış | D3: Paket Toplam | E3: Ersen Satış Tek | G3: TurKatilim standard sales | H3: =SUM(Satislistesi!C50:L50) -> 13250
A4: 1-Dresden | B4: 12 | C4: 0 | D4: =B4+C4 -> 12 | E4: =COUNTIF(Satislistesi!C3:C49,">0")-D4 -> 26 | G4: Child discount | H4: =Satislistesi!N50 -> -120
A5: 2-Tekne | B5: 0 | C5: 0 | D5: =B5+C5 -> 0 | E5: =COUNTIF(Satislistesi!D3:D49,">0")-D5 -> 31 | G5: TurKatilim grand total | H5: =Satislistesi!O50 -> 13130
A6: 3-KV | B6: 12 | C6: 0 | D6: =B6+C6 -> 12 | E6: =COUNTIF(Satislistesi!E3:E49,">0")-D6 -> 13 | G6: Package discount (separate) | H6: =Satislistesi!M50 -> -300
A7: 4-Çek G. | B7: 12 | C7: 0 | D7: =B7+C7 -> 12 | E7: =COUNTIF(Satislistesi!F3:F49,">0")-D7 -> 7 | G7: Final revenue after package | H7: =H5+H6 -> 12830
A8: 5-Tuna T. | B8: 0 | C8: 0 | D8: =B8+C8 -> 0 | E8: =COUNTIF(Satislistesi!G3:G49,">0")-D8 -> 29
A9: 6-Estergom | B9: 12 | C9: 0 | D9: =B9+C9 -> 12 | E9: =COUNTIF(Satislistesi!H3:H49,">0")-D9 -> 21
A10: 7-Çigan | B10: 0 | C10: 0 | D10: =B10+C10 -> 0 | E10: =COUNTIF(Satislistesi!I3:I49,">0")-D10 -> 6
A11: 8-Bratislava | B11: 12 | C11: 0 | D11: =B11+C11 -> 12 | E11: =COUNTIF(Satislistesi!J3:J49,">0")-D11 -> 16
A12: 9-Hallstatt | B12: 12 | C12: 0 | D12: =B12+C12 -> 12 | E12: =COUNTIF(Satislistesi!K3:K49,">0")-D12 -> 15
A13: 10-Konser | B13: 0 | C13: 0 | D13: =B13+C13 -> 0 | E13: =COUNTIF(Satislistesi!L3:L49,">0")-D13 -> 1
A14: TOPLAM | B14: =SUM(B4:B13) -> 72 | C14: =SUM(C4:C13) -> 0 | D14: =SUM(D4:D13) -> 72 | E14: =SUM(E4:E13) -> 165
A18: Kişi Bazında Satış Detayı
A19: İsim Soyad | B19: Satın Alınan Turlar | C19: Standart Toplam (€) | D19: Paket İndirimi (€) | E19: Renk İndirimi (€) | F19: Net Satış (€)
A20: AYSUNUYGUN | B20: 1-Dresden (40€), 2-Tekne (50€), 3-KV (60€), 4-Çek G. (65€), 5-Tuna T. (40€), 6-Estergom (60€), 7-Çigan (70€), 8-Bratislava (40€), 9-Hallstatt (100€), 10-Konser (65€) | C20: 590 | D20: 0 | E20: 0 | F20: 590
A21: Mehmet BarışAltun | B21: 1-Dresden (40€), 2-Tekne (50€), 3-KV (60€), 5-Tuna T. (40€), 6-Estergom (60€), 7-Çigan (70€), 9-Hallstatt (100€) | C21: 420 | D21: 0 | E21: 0 | F21: 420
A22: TugbaAltun | B22: 1-Dresden (40€), 2-Tekne (50€), 3-KV (60€), 5-Tuna T. (40€), 6-Estergom (60€), 7-Çigan (70€), 9-Hallstatt (100€) | C22: 420 | D22: 0 | E22: 0 | F22: 420
A23: Gül CananFettahlıoğlu | B23: 1-Dresden (40€), 3-KV (60€), 5-Tuna T. (40€), 6-Estergom (60€), 8-Bratislava (40€) | C23: 240 | D23: 0 | E23: 0 | F23: 240
A24: Ramazan YaşarFettahlıoğlu | B24: 1-Dresden (40€), 3-KV (60€), 5-Tuna T. (40€), 6-Estergom (60€), 8-Bratislava (40€) | C24: 240 | D24: 0 | E24: 0 | F24: 240
A25: Samiye NurFettahlıoğlu | B25: 1-Dresden (40€), 3-KV (60€), 5-Tuna T. (40€), 6-Estergom (60€), 8-Bratislava (40€) | C25: 240 | D25: 0 | E25: 0 | F25: 240
A26: Abdullah CemFettahlıoğlu | B26: 5-Tuna T. (40€), 6-Estergom (60€), 8-Bratislava (40€) | C26: 140 | D26: 0 | E26: 0 | F26: 140
A27: VacideSever | B27: 1-Dresden (40€), 3-KV (60€), 5-Tuna T. (40€), 6-Estergom (60€), 8-Bratislava (40€) | C27: 240 | D27: 0 | E27: 0 | F27: 240
A28: MetinMutlu | B28: 1-Dresden (40€), 3-KV (60€), 5-Tuna T. (40€), 6-Estergom (60€), 8-Bratislava (40€) | C28: 240 | D28: 0 | E28: 0 | F28: 240
A29: İBRAHİM HALİLERTAN | B29: 1-Dresden (40€), 3-KV (60€), 6-Estergom (60€), 8-Bratislava (40€) | C29: 200 | D29: 0 | E29: 0 | F29: 200
A30: TUBAERTAN | B30: 1-Dresden (40€), 3-KV (60€), 6-Estergom (60€), 8-Bratislava (40€) | C30: 200 | D30: 0 | E30: 0 | F30: 200
A31: BÜŞRA NEVİNERTAN | B31: Tur satışı yok | C31: 0 | D31: 0 | E31: 0 | F31: 0
... A66: SEDAT ÖZDEMİR | B66: 1-Dresden (40€), 2-Tekne (50€), 3-KV (60€), 4-Çek G. (65€), 5-Tuna T. (40€), 6-Estergom (60€), 7-Çigan (70€), 8-Bratislava (40€), 9-Hallstatt (100€) | C66: 525 | D66: -25 | E66: 0 | F66: 500
A67: TOPLAM | C67: =SUM(C20:C66) -> 13250 | D67: =SUM(D20:D66) -> -300 | E67: =SUM(E20:E66) -> -120 | F67: =SUM(F20:F66) -> 12830

Sheet Hesap
A1: Ersen Çelebi - PCS 1107 BE-PBV Hesap
A3: Kalem | B3: Detay | C3: Tutar (€) | D3: Adet | E3: Birim (€) | F3: Not
A4: Standart tur satış toplamı | B4: Satislistesi C:L toplamı | C4: =SUM(Satislistesi!C50:L50) -> 13250 | F4: Paket turları 12 kişi için tamamlandı
A5: Paket indirimi | B5: 12 x 25 EUR | C5: =Satislistesi!M50 -> -300 | D5: 12 | E5: 25 | F5: 365 EUR yerine 340 EUR
A6: Çocuk indirimi | B6: TurKatilim N2 | C6: =Satislistesi!N50 -> -120 | D6: 12 | E6: 10 | F6: Renkli işaretli 12 satış
A7: Düzeltilmiş toplam satış | B7: Standart + paket + çocuk indirimi | C7: =Satislistesi!O50+Satislistesi!M50 -> 12830
A8: Önceden alınan paket ödemeleri | B8: 12 x 340 EUR | C8: -4080 | D8: 12 | E8: 340 | F8: Nakit bakiyeden düşülür
A9: Belgelendirilmiş tur giderleri | B9: Harcamalar detay toplamı | C9: =-Harcamalar!I16 -> -1372 | F9: Kur ve eksik tutarlar girilince otomatik güncellenir
A10: Günlük hizmet bedeli | B10: Mutabık kalınan tutar | C10: -375
A11: Komisyon | B11: Mutabık kalınan tutar | C11: -750
A12: KALAN NAKİT | C12: =C7+SUM(C8:C11) -> 6253
A15: Gider Kontrolü
A16: Önceden bildirilen toplam gider | C16: 1442
A17: Detaylı belgelerden hesaplanan gider | C17: =Harcamalar!I16 -> 1372
A18: Eksik / açıklanmayan fark | C18: =C16-C17 -> 70

Sheet Satislistesi
A1: PCS 1107 BE-PBV - Ersen Satış Listesi
A2: İsim Soyad | B2: Geldi | C2: 1-Dresden (40€) | D2: 2-Tekne (50€) | E2: 3-KV (60€) | F2: 4-Çek G. (65€) | G2: 5-Tuna T. (40€) | H2: 6-Estergom (60€) | I2: 7-Çigan (70€) | J2: 8-Bratislava (40€) | K2: 9-Hallstatt (100€) | L2: 10-Konser (65€) | M2: Paket İndirimi | N2: Renk İndirimi | O2: TurKatilim Grand Total (€)
A3: =ExcusionSales!A4 -> AYSUNUYGUN | B3: =ExcusionSales!N4 -> FALSE | C3: =IF(ExcusionSales!B4,40,0) -> 40 | D3: =IF(ExcusionSales!C4,50,0) -> 50 | E3: =IF(ExcusionSales!D4,60,0) -> 60 | F3: =IF(ExcusionSales!E4,65,0) -> 65 | G3: =IF(ExcusionSales!F4,40,0) -> 40 | H3: =IF(ExcusionSales!G4,60,0) -> 60 | I3: =IF(ExcusionSales!H4,70,0) -> 70 | J3: =IF(ExcusionSales!I4,40,0) -> 40 | K3: =IF(ExcusionSales!J4,100,0) -> 100 | L3: =IF(ExcusionSales!L4,65,0) -> 65 | M3: 0 | N3: 0 | O3: =SUM(C3:L3)+N3 -> 590
A4: =ExcusionSales!A5 -> Mehmet BarışAltun | B4: =ExcusionSales!N5 -> FALSE | C4: =IF(ExcusionSales!B5,40,0) -> 40 | D4: =IF(ExcusionSales!C5,50,0) -> 50 | E4: =IF(ExcusionSales!D5,60,0) -> 60 | F4: =IF(ExcusionSales!E5,65,0) -> 0 | G4: =IF(ExcusionSales!F5,40,0) -> 40 | H4: =IF(ExcusionSales!G5,60,0) -> 60 | I4: =IF(ExcusionSales!H5,70,0) -> 70 | J4: =IF(ExcusionSales!I5,40,0) -> 0 | K4: =IF(ExcusionSales!J5,100,0) -> 100 | L4: =IF(ExcusionSales!L5,65,0) -> 0 | M4: 0 | N4: 0 | O4: =SUM(C4:L4)+N4 -> 420
A5: =ExcusionSales!A6 -> TugbaAltun | B5: =ExcusionSales!N6 -> FALSE | C5: =IF(ExcusionSales!B6,40,0) -> 40 | D5: =IF(ExcusionSales!C6,50,0) -> 50 | E5: =IF(ExcusionSales!D6,60,0) -> 60 | F5: =IF(ExcusionSales!E6,65,0) -> 0 | G5: =IF(ExcusionSales!F6,40,0) -> 40 | H5: =IF(ExcusionSales!G6,60,0) -> 60 | I5: =IF(ExcusionSales!H6,70,0) -> 70 | J5: =IF(ExcusionSales!I6,40,0) -> 0 | K5: =IF(ExcusionSales!J6,100,0) -> 100 | L5: =IF(ExcusionSales!L6,65,0) -> 0 | M5: 0 | N5: 0 | O5: =SUM(C5:L5)+N5 -> 420
A6: =ExcusionSales!A7 -> Gül CananFettahlıoğlu | B6: =ExcusionSales!N7 -> FALSE | C6: =IF(ExcusionSales!B7,40,0) -> 40 | D6: =IF(ExcusionSales!C7,50,0) -> 0 | E6: =IF(ExcusionSales!D7,60,0) -> 60 | F6: =IF(ExcusionSales!E7,65,0) -> 0 | G6: =IF(ExcusionSales!F7,40,0) -> 40 | H6: =IF(ExcusionSales!G7,60,0) -> 60 | I6: =IF(ExcusionSales!H7,70,0) -> 0 | J6: =IF(ExcusionSales!I7,40,0) -> 40 | K6: =IF(ExcusionSales!J7,100,0) -> 0 | L6: =IF(ExcusionSales!L7,65,0) -> 0 | M6: 0 | N6: 0 | O6: =SUM(C6:L6)+N6 -> 240
A7: =ExcusionSales!A8 -> Ramazan YaşarFettahlıoğlu | B7: =ExcusionSales!N8 -> FALSE | C7: =IF(ExcusionSales!B8,40,0) -> 40 | D7: =IF(ExcusionSales!C8,50,0) -> 0 | E7: =IF(ExcusionSales!D8,60,0) -> 60 | F7: =IF(ExcusionSales!E8,65,0) -> 0 | G7: =IF(ExcusionSales!F8,40,0) -> 40 | H7: =IF(ExcusionSales!G8,60,0) -> 60 | I7: =IF(ExcusionSales!H8,70,0) -> 0 | J7: =IF(ExcusionSales!I8,40,0) -> 40 | K7: =IF(ExcusionSales!J8,100,0) -> 0 | L7: =IF(ExcusionSales!L8,65,0) -> 0 | M7: 0 | N7: 0 | O7: =SUM(C7:L7)+N7 -> 240
A8: =ExcusionSales!A9 -> Samiye NurFettahlıoğlu | B8: =ExcusionSales!N9 -> FALSE | C8: =IF(ExcusionSales!B9,40,0) -> 40 | D8: =IF(ExcusionSales!C9,50,0) -> 0 | E8: =IF(ExcusionSales!D9,60,0) -> 60 | F8: =IF(ExcusionSales!E9,65,0) -> 0 | G8: =IF(ExcusionSales!F9,40,0) -> 40 | H8: =IF(ExcusionSales!G9,60,0) -> 60 | I8: =IF(ExcusionSales!H9,70,0) -> 0 | J8: =IF(ExcusionSales!I9,40,0) -> 40 | K8: =IF(ExcusionSales!J9,100,0) -> 0 | L8: =IF(ExcusionSales!L9,65,0) -> 0 | M8: 0 | N8: 0 | O8: =SUM(C8:L8)+N8 -> 240
A9: =ExcusionSales!A10 -> Abdullah CemFettahlıoğlu | B9: =ExcusionSales!N10 -> FALSE | C9: =IF(ExcusionSales!B10,40,0) -> 0 | D9: =IF(ExcusionSales!C10,50,0) -> 0 | E9: =IF(ExcusionSales!D10,60,0) -> 0 | F9: =IF(ExcusionSales!E10,65,0) -> 0 | G9: =IF(ExcusionSales!F10,40,0) -> 40 | H9: =IF(ExcusionSales!G10,60,0) -> 60 | I9: =IF(ExcusionSales!H10,70,0) -> 0 | J9: =IF(ExcusionSales!I10,40,0) -> 40 | K9: =IF(ExcusionSales!J10,100,0) -> 0 | L9: =IF(ExcusionSales!L10,65,0) -> 0 | M9: 0 | N9: 0 | O9: =SUM(C9:L9)+N9 -> 140
A10: =ExcusionSales!A11 -> VacideSever | B10: =ExcusionSales!N11 -> FALSE | C10: =IF(ExcusionSales!B11,40,0) -> 40 | D10: =IF(ExcusionSales!C11,50,0) -> 0 | E10: =IF(ExcusionSales!D11,60,0) -> 60 | F10: =IF(ExcusionSales!E11,65,0) -> 0 | G10: =IF(ExcusionSales!F11,40,0) -> 40 | H10: =IF(ExcusionSales!G11,60,0) -> 60 | I10: =IF(ExcusionSales!H11,70,0) -> 0 | J10: =IF(ExcusionSales!I11,40,0) -> 40 | K10: =IF(ExcusionSales!J11,100,0) -> 0 | L10: =IF(ExcusionSales!L11,65,0) -> 0 | M10: 0 | N10: 0 | O10: =SUM(C10:L10)+N10 -> 240
A11: =ExcusionSales!A12 -> MetinMutlu | B11: =ExcusionSales!N12 -> FALSE | C11: =IF(ExcusionSales!B12,40,0) -> 40 | D11: =IF(ExcusionSales!C12,50,0) -> 0 | E11: =IF(ExcusionSales!D12,60,0) -> 60 | F11: =IF(ExcusionSales!E12,65,0) -> 0 | G11: =IF(ExcusionSales!F12,40,0) -> 40 | H11: =IF(ExcusionSales!G12,60,0) -> 60 | I11: =IF(ExcusionSales!H12,70,0) -> 0 | J11: =IF(ExcusionSales!I12,40,0) -> 40 | K11: =IF(ExcusionSales!J12,100,0) -> 0 | L11: =IF(ExcusionSales!L12,65,0) -> 0 | M11: 0 | N11: 0 | O11: =SUM(C11:L11)+N11 -> 240
A12: =ExcusionSales!A13 -> İBRAHİM HALİLERTAN | B12: =ExcusionSales!N13 -> FALSE | C12: =IF(ExcusionSales!B13,40,0) -> 40 | D12: =IF(ExcusionSales!C13,50,0) -> 0 | E12: =IF(ExcusionSales!D13,60,0) -> 60 | F12: =IF(ExcusionSales!E13,65,0) -> 0 | G12: =IF(ExcusionSales!F13,40,0) -> 0 | H12: =IF(ExcusionSales!G13,60,0) -> 60 | I12: =IF(ExcusionSales!H13,70,0) -> 0 | J12: =IF(ExcusionSales!I13,40,0) -> 40 | K12: =IF(ExcusionSales!J13,100,0) -> 0 | L12: =IF(ExcusionSales!L13,65,0) -> 0 | M12: 0 | N12: 0 | O12: =SUM(C12:L12)+N12 -> 200
A13: =ExcusionSales!A14 -> TUBAERTAN | B13: =ExcusionSales!N14 -> FALSE | C13: =IF(ExcusionSales!B14,40,0) -> 40 | D13: =IF(ExcusionSales!C14,50,0) -> 0 | E13: =IF(ExcusionSales!D14,60,0) -> 60 | F13: =IF(ExcusionSales!E14,65,0) -> 0 | G13: =IF(ExcusionSales!F14,40,0) -> 0 | H13: =IF(ExcusionSales!G14,60,0) -> 60 | I13: =IF(ExcusionSales!H14,70,0) -> 0 | J13: =IF(ExcusionSales!I14,40,0) -> 40 | K13: =IF(ExcusionSales!J14,100,0) -> 0 | L13: =IF(ExcusionSales!L14,65,0) -> 0 | M13: 0 | N13: 0 | O13: =SUM(C13:L13)+N13 -> 200
A14: =ExcusionSales!A15 -> BÜŞRA NEVİNERTAN | B14: =ExcusionSales!N15 -> FALSE | C14: =IF(ExcusionSales!B15,40,0) -> 0 | D14: =IF(ExcusionSales!C15,50,0) -> 0 | E14: =IF(ExcusionSales!D15,60,0) -> 0 | F14: =IF(ExcusionSales!E15,65,0) -> 0 | G14: =IF(ExcusionSales!F15,40,0) -> 0 | H14: =IF(ExcusionSales!G15,60,0) -> 0 | I14: =IF(ExcusionSales!H15,70,0) -> 0 | J14: =IF(ExcusionSales!I15,40,0) -> 0 | K14: =IF(ExcusionSales!J15,100,0) -> 0 | L14: =IF(ExcusionSales!L15,65,0) -> 0 | M14: 0 | N14: 0 | O14: =SUM(C14:L14)+N14 -> 0
... A49: =ExcusionSales!A50 -> SEDAT ÖZDEMİR | B49: =ExcusionSales!N50 -> FALSE | C49: =IF(ExcusionSales!B50,40,0) -> 40 | D49: =IF(ExcusionSales!C50,50,0) -> 50 | E49: =IF(ExcusionSales!D50,60,0) -> 60 | F49: =IF(ExcusionSales!E50,65,0) -> 65 | G49: =IF(ExcusionSales!F50,40,0) -> 40 | H49: =IF(ExcusionSales!G50,60,0) -> 60 | I49: =IF(ExcusionSales!H50,70,0) -> 70 | J49: =IF(ExcusionSales!I50,40,0) -> 40 | K49: =IF(ExcusionSales!J50,100,0) -> 100 | L49: =IF(ExcusionSales!L50,65,0) -> 0 | M49: -25 | N49: 0 | O49: =SUM(C49:L49)+N49 -> 525
A50: TOPLAM | C50: =SUM(C3:C49) -> 1520 | D50: =SUM(D3:D49) -> 1550 | E50: =SUM(E3:E49) -> 1500 | F50: =SUM(F3:F49) -> 1235 | G50: =SUM(G3:G49) -> 1160 | H50: =SUM(H3:H49) -> 1980 | I50: =SUM(I3:I49) -> 420 | J50: =SUM(J3:J49) -> 1120 | ... O50: =SUM(O3:O49) -> 13130
